
```toc
```

## 简介：回调

我们经常需要用到异步调用，比如 `setTimeout` 就是。

下面看一个实际的例子，该函数使用给定的 `src` 加载脚本

```js
function loadScript(src) {
  // 创建一个 <script> 标签，并将其附加到页面
  // 这将使得具有给定 src 的脚本开始加载，并在加载完成后运行
  let script = document.createElement('script');
  script.src = src;
  document.head.append(script);
}
```

它将一个新的、带有给定 `src` 的、动态创建的标签 `<script src="…">` 插入到文档中。浏览器将自动开始加载它，并在加载完成后执行它。

我们可以像这样使用这个函数：

```js
// 在给定路径下加载并执行脚本
loadScript('/my/script.js');
```

脚本是“异步”调用的，因为它从现在开始加载，但是在这个加载函数执行完成后才运行。如果在 `loadScript(…)` 下面有任何其他代码，它们不会等到脚本加载完成才执行。

```js
loadScript('/my/script.js');
// loadScript 下面的代码
// 不会等到脚本加载完成才执行
// ...
```

假设我们需要在新脚本加载后立即使用它。它声明了新函数，我们想运行它们。但如果我们在 `loadScript(…)` 调用后立即执行此操作，这将不会有效。

```js
loadScript('/my/script.js'); // 这个脚本有 "function newFunction() {…}"

newFunction(); // 没有这个函数！
```

自然情况下，浏览器可能没有时间加载脚本。到目前为止，`loadScript` 函数并没有提供跟踪加载完成的方法。脚本加载并最终运行，仅此而已。但我们希望了解脚本何时加载完成，以使用其中的新函数和变量。

让我们添加一个 `callback` 函数作为 `loadScript` 的第二个参数，该函数应在脚本加载完成时执行：

```js
function loadScript(src, callback) {
  let script = document.createElement('script');
  script.src = src;

  script.onload = () => callback(script);

  document.head.append(script);
}
```

`onload` 事件在 [资源加载：onload，onerror](https://zh.javascript.info/onload-onerror#loading-a-script) 一文中有描述，它通常会在脚本加载和执行完成后执行一个函数。

现在，如果我们想调用该脚本中的新函数，我们应该将其写在回调函数中：

```js
loadScript('/my/script.js', function() {
  // 在脚本加载完成后，回调函数才会执行
  newFunction(); // 现在它工作了
  ...
});
```

这是我们的想法：第二个参数是一个函数（通常是匿名函数），该函数会在行为（action）完成时运行。这是一个带有真实脚本的可运行的示例：

```js
function loadScript(src, callback) {
  let script = document.createElement('script');
  script.src = src;
  script.onload = () => callback(script);
  document.head.append(script);
}

loadScript('https://cdnjs.cloudflare.com/ajax/libs/lodash.js/3.2.0/lodash.js', script => {
  alert(`酷，脚本 ${script.src} 加载完成`);
  alert( _ ); // _ 是所加载的脚本中声明的一个函数
});
```

或者可以写成这样

```js
function myCallback(script){
	alert(`酷，脚本 ${script.src} 加载完成`);
	alert( _ ); // _ 是所加载的脚本中声明的一个函数
}
loadScript('https://cdnjs.cloudflare.com/ajax/libs/lodash.js/3.2.0/lodash.js', myCallback);
```

### 在会调中回调

我们如何依次加载两个脚本：第一个，然后是第二个？自然的解决方案是将第二个 `loadScript` 调用放入回调中，如下所示：

```js
loadScript('/my/script.js', function(script) {

  alert(`酷，脚本 ${script.src} 加载完成，让我们继续加载另一个吧`);

  loadScript('/my/script2.js', function(script) {
    alert(`酷，第二个脚本加载完成`);
  });

});
```


### 处理 Error

在上述示例中，我们并没有考虑出现 error 的情况。如果脚本加载失败怎么办？我们的回调应该能够对此作出反应。这是 `loadScript` 的改进版本，可以跟踪加载错误：

```js
function loadScript(src, callback) {
  let script = document.createElement('script');
  script.src = src;

  script.onload = () => callback(null, script);
  script.onerror = () => callback(new Error(`Script load error for ${src}`));

  document.head.append(script);
}
```

加载成功时，它会调用 `callback(null, script)`，否则调用 `callback(error)`。用法：

```js
loadScript('/my/script.js', function(error, script) {
  if (error) {
    // 处理 error
  } else {
    // 脚本加载成功
  }
});
```


再次强调，我们在 `loadScript` 中所使用的方案其实很普遍。它被称为“Error 优先回调（error-first callback）”风格。

约定是：

1. `callback` 的第一个参数是为 error 而保留的。一旦出现 error，`callback(err)` 就会被调用。
2. 第二个参数（和下一个参数，如果需要的话）用于成功的结果。此时 `callback(null, result1, result2…)` 就会被调用。

因此，单一的 `callback` 函数可以同时具有报告 error 和传递返回结果的作用。

*注意：不要嵌套太多层*

## promise

案例：你是一位歌手，粉丝总是询问什么时候发新歌，于是你为了避免一直不断且重复的询问，你承诺（promise）会在单曲发布的第一时间发给他们。你给了粉丝们一个列表。他们可以在上面填写他们的电子邮件地址，以便当歌曲发布后，让所有订阅了的人能够立即收到。即便遇到不测，例如录音室发生了火灾，以致你无法发布新歌，他们也能及时收到相关通知。

```js
let promise = new Promise(function(resolve, reject) {
  // executor（生产者代码，“歌手”）
});
```

传递给 `new Promise` 的函数被称为 **executor**。当 `new Promise` 被创建，executor 会自动运行。它包含最终应产出结果的生产者代码。按照上面的类比：executor 就是“歌手”。

它的参数 `resolve` 和 `reject` 是由 JavaScript 自身提供的回调。我们的代码仅在 `executor` 的内部。当 ` executor ` 获得了结果，无论是早还是晚都没关系，它应该调用以下回调之一：

- `resolve(value)` —— 如果任务成功完成并带有结果 `value`。
- `reject(error)` —— 如果出现了 error，`error` 即为 error 对象。

所以总结一下就是：`executor` 会自动运行并尝试执行一项工作。尝试结束后，如果成功则调用 ` resolve `，如果出现 error 则调用 ` reject `。

由 `new Promise` 构造器返回的 `promise` 对象具有以下内部属性：

- `state` —— 最初是 `"pending"`，然后在 `resolve` 被调用时变为 `"fulfilled"`，或者在 `reject` 被调用时变为 `"rejected"`。
- `result` —— 最初是 `undefined`，然后在 `resolve(value)` 被调用时变为 `value`，或者在 `reject(error)` 被调用时变为 `error`。

下面是一个 promise 构造器和一个简单的 executor 函数，该 executor 函数具有包含时间（即 `setTimeout`）的“生产者代码”：

```js
let promise = new Promise(function(resolve, reject) {
  // 当 promise 被构造完成时，自动执行此函数

  // 1 秒后发出工作已经被完成的信号，并带有结果 "done"
  setTimeout(() => resolve("done"), 1000);
});
```

通过运行上面的代码，我们可以看到两件事儿：

1. executor 被自动且立即调用（通过 `new Promise`）。
    
2. executor 接受两个参数：`resolve` 和 `reject`。这些函数由 JavaScript 引擎预先定义，因此我们不需要创建它们。我们只需要在准备好（译注：指的是 executor 准备好）时调用其中之一即可。
    
    经过 1 秒的“处理”后，executor 调用 `resolve("done")` 来产生结果。这将改变 `promise` 对象的状态：从 `pending` 转换到`fulfilled`

这是一个成功完成任务的例子，一个“成功实现了的诺言”。下面则是一个 executor 以 error 拒绝 promise 的示例：

```js
let promise = new Promise(function(resolve, reject) {
  // 1 秒后发出工作已经被完成的信号，并带有 error
  setTimeout(() => reject(new Error("Whoops!")), 1000);
});
```

对 `reject(...)` 的调用将 promise 对象的状态移至 `"rejected"`。

总而言之，executor 应该执行一项工作（通常是需要花费一些时间的事儿），然后调用 `resolve` 或 `reject` 来改变对应的 promise 对象的状态。与最初的 “pending” promise 相反，一个 resolved 或 rejected 的 promise 都会被称为 “settled”。

**这只能有一个结果或一个 error**
>executor 只能调用一个 `resolve` 或一个 `reject`。任何状态的更改都是最终的。
所有其他的再对 `resolve` 和 `reject` 的调用都会被忽略：
```js
let promise = new Promise(function(resolve, reject) {
  resolve("done");

  reject(new Error("…")); // 被忽略
  setTimeout(() => resolve("…")); // 被忽略
});
```
这的宗旨是，一个被 executor 完成的工作只能有一个结果或一个 error。并且，`resolve/reject` 只需要一个参数（或不包含任何参数），并且将忽略额外的参数。

**resolve/reject 可以立即进行**

实际上，executor 通常是异步执行某些操作，并在一段时间后调用 `resolve/reject`，但这不是必须的。我们还可以立即调用 `resolve` 或 `reject`，就像这样：
```js
let promise = new Promise(function(resolve, reject) {
  // 不花时间去做这项工作
  resolve(123); // 立即给出结果：123
});
```

### 消费者：then，catch

Promise 对象充当的是 executor（“生产者代码”或“歌手”）和消费函数（“粉丝”）之间的连接，后者将接收结果或 error。可以通过使用 `.then` 和 `.catch` 方法注册消费函数。

#### then

```js
promise.then(
  function(result) { /* handle a successful result */ },
  function(error) { /* handle an error */ }
);
```

`.then` 的第一个参数是一个函数，该函数将在 promise resolved 且接收到结果后执行。
`.then` 的第二个参数也是一个函数，该函数将在 promise rejected 且接收到 error 信息后执行。

例如，以下是对成功 resolved 的 promise 做出的反应：

```js
let promise = new Promise(function(resolve, reject) {
  setTimeout(() => resolve("done!"), 1000);
});

// resolve 运行 .then 中的第一个函数
promise.then(
  result => alert(result), // 1 秒后显示 "done!"
  error => alert(error) // 不运行
);
```

第一个函数被运行了。在 reject 的情况下，运行第二个：

```js
let promise = new Promise(function(resolve, reject) {
  setTimeout(() => reject(new Error("Whoops!")), 1000);
});

// reject 运行 .then 中的第二个函数
promise.then(
  result => alert(result), // 不运行
  error => alert(error) // 1 秒后显示 "Error: Whoops!"
);
```

如果我们只对成功完成的情况感兴趣，那么我们可以只为 `.then` 提供一个函数参数：

```js
let promise = new Promise(resolve => {
  setTimeout(() => resolve("done!"), 1000);
});

promise.then(alert); // 1 秒后显示 "done!"
```


#### Catch

如果我们只对 error 感兴趣，那么我们可以使用 `null` 作为第一个参数：`.then(null, errorHandlingFunction)`。或者我们也可以使用 `.catch(errorHandlingFunction)`，其实是一样的：

```js
let promise = new Promise((resolve, reject) => {
  setTimeout(() => reject(new Error("Whoops!")), 1000);
});

// .catch(f) 与 promise.then(null, f) 一样
promise.catch(alert); // 1 秒后显示 "Error: Whoops!"
```

`.catch(f)` 调用是 `.then(null, f)` 的完全的模拟，它只是一个简写形式。

###  清理：finally

```js
new Promise((resolve, reject) => {
  /* 做一些需要时间的事，之后调用可能会 resolve 也可能会 reject */
})
  // 在 promise 为 settled 时运行，无论成功与否
  .finally(() => stop loading indicator)
  // 所以，加载指示器（loading indicator）始终会在我们继续之前停止
  .then(result => show result, err => show error)
```

请注意，`finally(f)` 并不完全是 `then(f,f)` 的别名。

它们之间有重要的区别：

1. `finally` 处理程序（handler）没有参数。在 `finally` 中，我们不知道 promise 是否成功。没关系，因为我们的任务通常是执行“常规”的完成程序（finalizing procedures）。
    请看上面的例子：如你所见，`finally` 处理程序没有参数，promise 的结果由下一个处理程序处理。
    
2. `finally` 处理程序将结果或 error “传递”给下一个合适的处理程序。
    
    例如，在这结果被从 `finally` 传递给了 `then`：
```js
new Promise((resolve, reject) => {
  setTimeout(() => resolve("value"), 2000)
})
  .finally(() => alert("Promise ready")) // 先触发
  .then(result => alert(result)); // <-- .then 显示 "value"
```

第一个 promise 返回的 `value` 通过 `finally` 被传递给了下一个 `then`。

这非常方便，因为 `finally` 并不意味着处理一个 promise 的结果。如前所述，无论结果是什么，它都是进行常规清理的地方。

下面是一个 promise 返回结果为 error 的示例，让我们看看它是如何通过 `finally` 被传递给 `catch` 的：

```js
new Promise((resolve, reject) => {
  throw new Error("error");
})
  .finally(() => alert("Promise ready")) // 先触发
  .catch(err => alert(err));  // <-- .catch 显示这个 error
```

3. `finally` 处理程序也不应该返回任何内容。如果它返回了，返回的值会默认被忽略。
    
    此规则的唯一例外是当 `finally` 处理程序抛出 error 时。此时这个 error（而不是任何之前的结果）会被转到下一个处理程序。

总结：

- `finally` 处理程序没有得到前一个处理程序的结果（它没有参数）。而这个结果被传递给了下一个合适的处理程序。
- 如果 `finally` 处理程序返回了一些内容，那么这些内容会被忽略。
- 当 `finally` 抛出 error 时，执行将转到最近的 error 的处理程序。

如果我们正确使用 `finally`（将其用于常规清理），那么这些功能将很有用。

### 对 settled 的 promise 的附加处理程序

如果 promise 为 pending 状态，`.then/catch/finally` 处理程序（handler）将等待它的结果。有时候，当我们向一个 promise 添加处理程序时，它可能已经 settled 了。在这种情况下，**这些处理程序会立即执行**：

```js
// 下面这 promise 在被创建后立即变为 resolved 状态
let promise = new Promise(resolve => resolve("done!"));
// 这里是立即执行
promise.then(alert); // done!（现在显示）
```

### 示例：loadScript

基本写法

```js
function loadScript(src, callback) {
  let script = document.createElement('script');
  script.src = src;

  script.onload = () => callback(null, script);
  script.onerror = () => callback(new Error(`Script load error for ${src}`));

  document.head.append(script);
}
```

使用 promise 重写

```js
function loadScript(src) {
  return new Promise(function(resolve, reject) {
    let script = document.createElement('script');
    script.src = src;

    script.onload = () => resolve(script);
    script.onerror = () => reject(new Error(`Script load error for ${src}`));

    document.head.append(script);
  });
}
```

用法

```js
let promise = loadScript("https://cdnjs.cloudflare.com/ajax/libs/lodash.js/4.17.11/lodash.js");

promise.then(
  script => alert(`${script.src} is loaded!`),
  error => alert(`Error: ${error.message}`)
);

promise.then(script => alert('Another handler...'));
```



## Promise 链

我们有一系列的异步任务要一个接一个地执行 —— 例如，加载脚本。我们如何写出更好的代码呢？Promise 提供了一些方案来做到这一点。

```js
new Promise(function(resolve, reject) {

  setTimeout(() => resolve(1), 1000); // (*)

}).then(function(result) { // (**)

  alert(result); // 1
  return result * 2;

}).then(function(result) { // (***)

  alert(result); // 2
  return result * 2;

}).then(function(result) {

  alert(result); // 4
  return result * 2;

});
```

它的想法是通过 `.then` 处理程序（handler）链进行传递 result。

运行流程如下：

1. 初始 promise 在 1 秒后 resolve `(*)`，
2. 然后 `.then` 处理程序被调用 `(**)`，它又创建了一个新的 promise（以 `2` 作为值 resolve）。
3. 下一个 `then` `(***)` 得到了前一个 `then` 的值，对该值进行处理（*2）并将其传递给下一个处理程序。
4. ……依此类推。
随着 result 在处理程序链中传递，我们可以看到一系列的 `alert` 调用：`1` → `2` → `4`。

这样之所以是可行的，是因为每个对 `.then` 的调用都会返回了一个新的 promise，因此我们可以在其之上调用下一个 `.then`。

当处理程序返回一个值时，它将成为该 promise 的 result，所以将使用它调用下一个 `.then`。

**新手常犯的一个经典错误：从技术上讲，我们也可以将多个 `.then` 添加到一个 promise 上。但这并不是 promise 链（chaining）。例如**：

```js
let promise = new Promise(function(resolve, reject) {
  setTimeout(() => resolve(1), 1000);
});

promise.then(function(result) {
  alert(result); // 1
  return result * 2;
});

promise.then(function(result) {
  alert(result); // 1
  return result * 2;
});

promise.then(function(result) {
  alert(result); // 1
  return result * 2;
});
```

我们在这里所做的只是一个 promise 的几个处理程序。它们不会相互传递 result；相反，它们之间彼此独立运行处理任务。

### 返回 promise

`.then(handler)` 中所使用的处理程序（handler）可以创建并返回一个 promise。在这种情况下，其他的处理程序将等待它 settled 后再获得其结果。例如：

```js
new Promise(function(resolve, reject) {
  setTimeout(() => resolve(1), 1000);
}).then(function(result) {

  alert(result); // 1

  return new Promise((resolve, reject) => { // (*)
    setTimeout(() => resolve(result * 2), 1000);
  });

}).then(function(result) { // (**)

  alert(result); // 2

  return new Promise((resolve, reject) => {
    setTimeout(() => resolve(result * 2), 1000);
  });

}).then(function(result) {

  alert(result); // 4

});
```

这里第一个 `.then` 显示 `1` 并在 `(*)` 行返回 `new Promise(…)`。1 秒后它会进行 resolve，然后 result（`resolve` 的参数，在这里它是 `result*2`）被传递给第二个 `.then` 的处理程序。这个处理程序位于 `(**)` 行，它显示 `2`，并执行相同的行为。

所以输出与前面的示例相同：1 → 2 → 4，但是现在在每次 `alert` 调用之间会有 1 秒钟的延迟。返回 promise 使我们能够构建异步行为链。

### `Thenables`

处理程序返回的不完全是一个 promise，而是返回的被称为 “thenable” 对象 —— 一个具有方法 `.then` 的任意对象。它会被当做一个 promise 来对待。

这个想法是，第三方库可以实现自己的“promise 兼容（promise-compatible）”对象。它们可以具有扩展的方法集，但也与原生的 promise 兼容，因为它们实现了 `.then` 方法。

这是一个 thenable 对象的示例：

```js
class Thenable {
  constructor(num) {
    this.num = num;
  }
  then(resolve, reject) {
    alert(resolve); // function() { native code }
    // 1 秒后使用 this.num*2 进行 resolve
    setTimeout(() => resolve(this.num * 2), 1000); // (**)
  }
}

new Promise(resolve => resolve(1))
  .then(result => {
    return new Thenable(result); // (*)
  })
  .then(alert); // 1000ms 后显示 2
```

这样允许我们将自定义的对象与 promise 链集成在一起，而不必继承自 `Promise`。

### 更复杂的示例：fetch

在前端编程中，promise 通常被用于网络请求。那么，让我们一起来看一个相关的扩展示例吧。

我们将使用 [fetch](https://zh.javascript.info/fetch) 方法从远程服务器加载用户信息。它有很多可选的参数，我们在 [单独的一章](https://zh.javascript.info/fetch) 中对其进行了详细介绍，但基本语法很简单：

```js
let promise = fetch(url);
```
执行这条语句，向 `url` 发出网络请求并返回一个 promise。当远程服务器返回 header（是在 **全部响应加载完成前**）时，该 promise 使用一个 `response` 对象来进行 resolve。

为了读取完整的响应，我们应该调用 `response.text()` 方法：当全部文字内容从远程服务器下载完成后，它会返回一个 promise，该 promise 以刚刚下载完成的这个文本作为 result 进行 resolve。

下面这段代码向 `user.json` 发送请求，并从服务器加载该文本：

```js
fetch('/article/promise-chaining/user.json')
  // 当远程服务器响应时，下面的 .then 开始执行
  .then(function(response) {
    // 当 user.json 加载完成时，response.text() 会返回一个新的 promise
    // 该 promise 以加载的 user.json 为 result 进行 resolve
    return response.text();
  })
  .then(function(text) {
    // ……这是远程文件的内容
    alert(text); // {"name": "iliakan", "isAdmin": true}
  });

// 或更简洁点
// 同上，但使用 response.json() 将远程内容解析为 JSON
fetch('/article/promise-chaining/user.json')
  .then(response => response.json())
  .then(user => alert(user.name)); // iliakan，获取到了用户名
```

例如，我们可以再向 GitHub 发送一个请求，加载用户个人资料并显示头像：

```js
// 发送一个对 user.json 的请求
fetch('/article/promise-chaining/user.json')
  // 将其加载为 JSON
  .then(response => response.json())
  // 发送一个到 GitHub 的请求
  .then(user => fetch(`https://api.github.com/users/${user.name}`))
  // 将响应加载为 JSON
  .then(response => response.json())
  // 显示头像图片（githubUser.avatar_url）3 秒（也可以加上动画效果）
  .then(githubUser => {
    let img = document.createElement('img');
    img.src = githubUser.avatar_url;
    img.className = "promise-avatar-example";
    document.body.append(img);
    setTimeout(() => img.remove(), 3000); // (*)
  });
```

这段代码可以工作，具体细节请看注释。但是，这有一个潜在的问题，一个新手使用 promise 时的典型问题。

请看 `(*)` 行：我们如何能在头像显示结束并被移除 **之后** 做点什么？例如，我们想显示一个用于编辑该用户或者其他内容的表单。就目前而言，是做不到的。其实就是因为 remove 方法后没有返回值，也就是不能继续往后使用 then 方法。

为了使链可扩展，我们需要返回一个在头像显示结束时进行 resolve 的 promise。

就像这样：

```js
fetch('/article/promise-chaining/user.json')
  .then(response => response.json())
  .then(user => fetch(`https://api.github.com/users/${user.name}`))
  .then(response => response.json())
  .then(githubUser => new Promise(function(resolve, reject) { // (*)
    let img = document.createElement('img');
    img.src = githubUser.avatar_url;
    img.className = "promise-avatar-example";
    document.body.append(img);

    setTimeout(() => {
      img.remove();
      resolve(githubUser); // (**)
    }, 3000);
  }))
  // 3 秒后触发
  .then(githubUser => alert(`Finished showing ${githubUser.name}`));
```

也就是说，第 `(*)` 行的 `.then` 处理程序现在返回一个 `new Promise`，只有在 `setTimeout` 中的 `resolve(githubUser)` `(**)` 被调用后才会变为 settled。链中的下一个 `.then` 将一直等待这一时刻的到来。

但是我们是否可以这样呢？

```js
fetch('/article/promise-chaining/user.json')
  // 将其加载为 JSON
  .then(response => response.json())
  // 发送一个到 GitHub 的请求
  .then(user => fetch(`https://api.github.com/users/${user.name}`))
  // 将响应加载为 JSON
  .then(response => response.json())
  // 显示头像图片（githubUser.avatar_url）3 秒（也可以加上动画效果）
  .then(githubUser => {
    let img = document.createElement('img');
    img.src = githubUser.avatar_url;
    img.className = "promise-avatar-example";
    document.body.append(img);

    setTimeout(() => {
      img.remove();
      resolve(githubUser); // (**)
    }, 3000);
  })
  .then(githubUser => alert(`Finished showing ${githubUser.name}`));
```

这是不行的，因为我们使用了 resolve，但是却没有定义。像前面几个 then 方法中都是有定义 resolve 方法的。所以需要先定义，可以修改成这样

```js
 .then(githubUser => {
    let img = document.createElement('img');
    img.src = githubUser.avatar_url;
    img.className = "promise-avatar-example";
    document.body.append(img);
    return new Promise(resolve => {
      setTimeout(() => {
        img.remove();
        resolve(githubUser);
      }, 3000);
    });
  })
  .then(githubUser => alert(`Finished showing ${githubUser.name}`));
```

作为一个好的做法，异步行为应该始终返回一个 promise。这样就可以使得之后我们计划后续的行为成为可能。即使我们现在不打算对链进行扩展，但我们之后可能会需要。

最后，我们可以将代码拆分为可重用的函数：

```js
function loadJson(url) {
  return fetch(url)
    .then(response => response.json());
}

function loadGithubUser(name) {
  return loadJson(`https://api.github.com/users/${name}`);
}

function showAvatar(githubUser) {
  return new Promise(function(resolve, reject) {
    let img = document.createElement('img');
    img.src = githubUser.avatar_url;
    img.className = "promise-avatar-example";
    document.body.append(img);

    setTimeout(() => {
      img.remove();
      resolve(githubUser);
    }, 3000);
  });
}

// 使用它们：
loadJson('/article/promise-chaining/user.json')
  .then(user => loadGithubUser(user.name))
  .then(showAvatar)
  .then(githubUser => alert(`Finished showing ${githubUser.name}`));
  // ...
```


## 使用 promise 进行错误处理

promise 链在错误（error）处理中十分强大。当一个 promise 被 reject 时，控制权将移交至最近的 rejection 处理程序。

例如，下面代码中所 `fetch` 的 URL 是错的（没有这个网站），`.catch` 对这个 error 进行了处理：

```js
fetch('https://no-such-server.blabla') // reject
  .then(response => response.json())
  .catch(err => alert(err)) // TypeError: Failed to fetch（这里的文字可能有所不同）
```

### 隐式 `try...catch`

promise 的执行者（executor）和 promise 的处理程序周围有一个“隐式的 `try..catch`”。如果发生异常，它就会被捕获，并被视为 rejection 进行处理。

例如

```js
new Promise((resolve, reject) => {
  throw new Error("Whoops!");
}).catch(alert); // Error: Whoops!
```

等同于

```js
new Promise((resolve, reject) => {
  reject(new Error("Whoops!"));
}).catch(alert); // Error: Whoops!
```

在 executor 周围的“隐式 `try..catch`”自动捕获了 error，并将其变为 rejected promise。

### 再次抛出

```js
// 执行流：catch -> then
new Promise((resolve, reject) => {

  throw new Error("Whoops!");

}).catch(function(error) {

  alert("The error is handled, continue normally");

}).then(() => alert("Next successful handler runs"));
```

### 未处理的 rejection

如果我们没有手动捕获相关异常，那么 js 会生成一个全局的 error。在浏览器中，我们可以使用 `unhandledrejection` 事件来捕获这类 error：

```js
window.addEventListener('unhandledrejection', function(event) {
  // 这个事件对象有两个特殊的属性：
  alert(event.promise); // [object Promise] —— 生成该全局 error 的 promise
  alert(event.reason); // Error: Whoops! —— 未处理的 error 对象
});

new Promise(function() {
  throw new Error("Whoops!");
}); // 没有用来处理 error 的 catch
```

### promise API

#### all

```js
let promise = Promise.all(iterable);
```

接受一个可迭代对象（通常是一个数组项为 promise 的数组），并返回一个新的 promise。

当所有给定的 promise 都 resolve 时，新的 promise 才会 resolve，并且其结果数组将成为新 promise 的结果。例如，下面的 `Promise.all` 在 3 秒之后 settled，然后它的结果就是一个 `[1, 2, 3]` 数组：

```js
Promise.all([
  new Promise(resolve => setTimeout(() => resolve(1), 3000)), // 1
  new Promise(resolve => setTimeout(() => resolve(2), 2000)), // 2
  new Promise(resolve => setTimeout(() => resolve(3), 1000))  // 3
]).then(alert); // 1,2,3 当上面这些 promise 准备好时：每个 promise 都贡献了数组中的一个元素
```

这个其实就是一个顺序执行。一个常见的技巧是，将一个任务数据数组映射（map）到一个 promise 数组，然后将其包装到 `Promise.all`。例如，如果我们有一个存储 URL 的数组，我们可以像这样 fetch 它们：

```js
let urls = [
  'https://api.github.com/users/iliakan',
  'https://api.github.com/users/remy',
  'https://api.github.com/users/jeresig'
];

// 将每个 url 映射（map）到 fetch 的 promise 中
let requests = urls.map(url => fetch(url));

// Promise.all 等待所有任务都 resolved
Promise.all(requests)
  .then(responses => responses.forEach(
    response => alert(`${response.url}: ${response.status}`)
  ));
```

一个更真实的示例，通过 GitHub 用户名来获取一个 GitHub 用户数组中用户的信息（我们也可以通过商品 id 来获取商品数组中的商品信息，逻辑都是一样的）：

```js
let names = ['iliakan', 'remy', 'jeresig'];

let requests = names.map(name => fetch(`https://api.github.com/users/${name}`));

Promise.all(requests)
  .then(responses => {
    // 所有响应都被成功 resolved
    for(let response of responses) {
      alert(`${response.url}: ${response.status}`); // 对应每个 url 都显示 200
    }
    return responses;
  })
  // 将响应数组映射（map）到 response.json() 数组中以读取它们的内容
  .then(responses => Promise.all(responses.map(r => r.json())))
  // 所有 JSON 结果都被解析："users" 是它们的数组
  .then(users => users.forEach(user => alert(user.name)));
```

**如果任意一个 promise 被 reject，由 `Promise.all` 返回的 promise 就会立即 reject，并且带有的就是这个 error。**

例如：

```js
Promise.all([
  new Promise((resolve, reject) => setTimeout(() => resolve(1), 1000)),
  new Promise((resolve, reject) => setTimeout(() => reject(new Error("Whoops!")), 2000)),
  new Promise((resolve, reject) => setTimeout(() => resolve(3), 3000))
]).catch(alert); // Error: Whoops!
```

这里的第二个 promise 在两秒后 reject。这立即导致了 `Promise.all` 的 reject，因此 `.catch` 执行了：被 reject 的 error 成为了整个 `Promise.all`的结果。

`Promise.all(iterable)` 允许在 `iterable` 中使用非 promise 的“常规”值

通常，`Promise.all(...)` 接受含有 promise 项的可迭代对象（大多数情况下是数组）作为参数。但是，如果这些对象中的任何一个不是 promise，那么它将被“按原样”传递给结果数组。例如，这里的结果是 `[1, 2, 3]`：

```js
Promise.all([
  new Promise((resolve, reject) => {
    setTimeout(() => resolve(1), 1000)
  }),
  2,
  3
]).then(alert); // 1, 2, 3
```


#### allSettled

如果任意的 promise reject，则 `Promise.all` 整个将会 reject。当我们需要 **所有** 结果都成功时，它对这种“全有或全无”的情况很有用：

```js
Promise.all([
  fetch('/template.html'),
  fetch('/style.css'),
  fetch('/data.json')
]).then(render); // render 方法需要所有 fetch 的数据
```

`Promise.allSettled` 等待所有的 promise 都被 settle，无论结果如何。结果数组具有：

- `{status:"fulfilled", value:result}` 对于成功的响应，
- `{status:"rejected", reason:error}` 对于 error。

例如，我们想要获取（fetch）多个用户的信息。即使其中一个请求失败，我们仍然对其他的感兴趣。

让我们使用 `Promise.allSettled`：

```js
let urls = [
  'https://api.github.com/users/iliakan',
  'https://api.github.com/users/remy',
  'https://no-such-url'
];

Promise.allSettled(urls.map(url => fetch(url)))
  .then(results => { // (*)
    results.forEach((result, num) => {
      if (result.status == "fulfilled") {
        alert(`${urls[num]}: ${result.value.status}`);
      }
      if (result.status == "rejected") {
        alert(`${urls[num]}: ${result.reason}`);
      }
    });
  });
```

上面的 `(*)` 行中的 `results` 将会是：

```js
[
  {status: 'fulfilled', value: ...response...},
  {status: 'fulfilled', value: ...response...},
  {status: 'rejected', reason: ...error object...}
]
```

**`Polyfill`**

如果浏览器不支持 `Promise.allSettled`，很容易进行 `polyfill`：

```js
if (!Promise.allSettled) {
  const rejectHandler = reason => ({ status: 'rejected', reason });

  const resolveHandler = value => ({ status: 'fulfilled', value });

  Promise.allSettled = function (promises) {
    const convertedPromises = promises.map(p => Promise.resolve(p).then(resolveHandler, rejectHandler));
    return Promise.all(convertedPromises);
  };
}
```
在这段代码中，`promises.map` 获取输入值，并通过 `p => Promise.resolve(p)` 将输入值转换为 promise（以防传递了非 promise 值），然后向每一个 promise 都添加 `.then` 处理程序。

这个处理程序将成功的结果 `value` 转换为 `{status:'fulfilled', value}`，将 error `reason` 转换为 `{status:'rejected', reason}`。这正是 `Promise.allSettled` 的格式。


#### race

与 `Promise.all` 类似，但只等待第一个 settled 的 promise 并获取其结果（或 error）。

```js
let promise = Promise.race(iterable);
```

例如，这里的结果将是 `1`：

```js
Promise.race([
  new Promise((resolve, reject) => setTimeout(() => resolve(1), 1000)),
  new Promise((resolve, reject) => setTimeout(() => reject(new Error("Whoops!")), 2000)),
  new Promise((resolve, reject) => setTimeout(() => resolve(3), 3000))
]).then(alert); // 1
```


#### any

与 `Promise.race` 类似，区别在于 `Promise.any` 只等待第一个 fulfilled 的 promise，并将这个 fulfilled 的 promise 返回。如果给出的 promise 都 rejected，那么返回的 promise 会带有 [`AggregateError`](https://developer.mozilla.org/zh/docs/Web/JavaScript/Reference/Global_Objects/AggregateError) —— 一个特殊的 error 对象，在其 `errors` 属性中存储着所有 promise error。

```js
let promise = Promise.any(iterable);
```

例如，这里的结果将是 `1`：

```js
Promise.any([
  new Promise((resolve, reject) => setTimeout(() => reject(new Error("Whoops!")), 1000)),
  new Promise((resolve, reject) => setTimeout(() => resolve(1), 2000)),
  new Promise((resolve, reject) => setTimeout(() => resolve(3), 3000))
]).then(alert); // 1
```

#### `resolve/reject`

在现代的代码中，很少需要使用 `Promise.resolve` 和 `Promise.reject` 方法，因为 `async/await` 语法（我们会在 [稍后](https://zh.javascript.info/async-await) 讲到）使它们变得有些过时了。

```js
// 用得少
let promise = new Promise(resolve => resolve(value));

// 几乎不用
let promise = new Promise((resolve, reject) => reject(error));
```

## `promisification`

对于一个简单的转换来说 “Promisification” 是一个长单词。它指将一个接受回调的函数转换为一个返回 promise 的函数。

由于许多函数和库都是基于回调的，因此，在实际开发中经常会需要进行这种转换。因为使用 promise 更加方便，所以将基于回调的函数和库 promise 化是有意义的。

为了更好地理解，让我们来看一个例子。

```js
function loadScript(src, callback) {
  let script = document.createElement('script');
  script.src = src;

  script.onload = () => callback(null, script);
  script.onerror = () => callback(new Error(`Script load error for ${src}`));

  document.head.append(script);
}

// 用法：
// loadScript('path/script.js', (err, script) => {...})
```

现在将其 promise 化

```js
let loadScriptPromise = function(src) {
  return new Promise((resolve, reject) => {
    loadScript(src, (err, script) => {
      if (err) reject(err);
      else resolve(script);
    });
  });
};

// 用法：
// loadScriptPromise('path/script.js').then(...)
```

在实际开发中，我们可能需要 promise 化很多函数，所以使用一个 helper（辅助函数）很有意义。

我们将其称为 `promisify(f)`：它接受一个需要被 promise 化的函数 `f`，并返回一个包装（wrapper）函数。

```js
function promisify(f) {
  return function (...args) { // 返回一个包装函数（wrapper-function） (*)
    return new Promise((resolve, reject) => {
      function callback(err, result) { // 我们对 f 的自定义的回调 (**)
        if (err) {
          reject(err);
        } else {
          resolve(result);
        }
      }

      args.push(callback); // 将我们的自定义的回调附加到 f 参数（arguments）的末尾
      f.call(this, ...args); // 调用原始的函数
    });
  };
}

// 用法：
let loadScriptPromise = promisify(loadScript);
loadScriptPromise(...).then(...);
```

这里其实就是 `promisify` 返回一个包装函数，包装函数参数就是 `loadScript` 的参数，而 `loadScript` 的回调函数会在 then 中调用。

在这里，`promisify` 假设原始函数期望一个带有两个参数 `(err, result)` 的回调。这就是我们最常遇到的形式。那么我们自定义的回调的格式是完全正确的，在这种情况下 `promisify` 也可以完美地运行。

但是如果原始的 `f` 期望一个带有更多参数的回调 `callback(err, res1, res2, ...)`，该怎么办呢？

我们可以继续改进我们的辅助函数。让我们写一个更高阶版本的 `promisify`。

- 当它被以 `promisify(f)` 的形式调用时，它应该以与上面那个版本的实现的工作方式类似。
- 当它被以 `promisify(f, true)` 的形式调用时，它应该返回以回调函数数组为结果 resolve 的 promise。这就是具有很多个参数的回调的结果。

```js
// promisify(f, true) 来获取结果数组
function promisify(f, manyArgs = false) {
  return function (...args) {
    return new Promise((resolve, reject) => {
      function callback(err, ...results) { // 我们自定义的 f 的回调
        if (err) {
          reject(err);
        } else {
          // 如果 manyArgs 被指定，则使用所有回调的结果 resolve
          resolve(manyArgs ? results : results[0]);
        }
      }

      args.push(callback);

      f.call(this, ...args);
    });
  };
}

// 用法：
f = promisify(f, true);
f(...).then(arrayOfResults => ..., err => ...);
```


## 微任务

promise 的处理程序 `.then`、`.catch` 和 `.finally` 都是异步的。

即便一个 promise 立即被 resolve，`.then`、`.catch` 和 `.finally` **下面** 的代码也会在这些处理程序之前被执行。

示例代码如下：

```js
let promise = Promise.resolve();

promise.then(() => alert("promise done!"));

alert("code finished"); // 这个 alert 先显示
```

#### 微任务队列

异步任务需要适当的管理。为此，ECMA 标准规定了一个内部队列 `PromiseJobs`，通常被称为“微任务队列（microtask queue）”（V8 术语）。

如 [规范](https://tc39.github.io/ecma262/#sec-jobs-and-job-queues) 中所述：

- 队列（queue）是先进先出的：首先进入队列的任务会首先运行。
- 只有在 JavaScript 引擎中没有其它任务在运行时，才开始执行任务队列中的任务。

简单地说，当一个 promise 准备就绪时，它的 `.then/catch/finally` 处理程序就会被放入队列中：但是它们不会立即被执行。当 JavaScript 引擎执行完当前的代码，它会从队列中获取任务并执行它。

**如果执行顺序对我们很重要该怎么办？我们怎么才能让 `code finished` 在 `promise done` 之后出现呢？**

很简单，只需要像下面这样使用 `.then` 将其放入队列：

```js
Promise.resolve()
  .then(() => alert("promise done!"))
  .then(() => alert("code finished"));
```


## `async/await`

### `async function`

以 `async` 这个关键字开始。它可以被放置在一个函数前面，如下所示

```js
async function f() {
  return 1;
}
```

在函数前面的 “async” 这个单词表达了一个简单的事情：即这个函数总是返回一个 promise。其他值将自动被包装在一个 resolved 的 promise 中。当然也可以显式地返回一个 promise，结果是一样的：

```js
async function f() {
  return Promise.resolve(1);
}

f().then(alert); // 1
```


### await

```js
// 只在 async 函数内工作
let value = await promise;
```

关键字 `await` 让 JavaScript 引擎等待直到 promise 完成（settle）并返回结果。这里的例子就是一个 1 秒后 resolve 的 promise：

```js
async function f() {

  let promise = new Promise((resolve, reject) => {
    setTimeout(() => resolve("done!"), 1000)
  });

  let result = await promise; // 等待，直到 promise resolve (*)
  alert(result); // "done!"
}

f();
```

让我们强调一下：`await` 实际上会暂停函数的执行，直到 promise 状态变为 settled，然后以 promise 的结果继续执行。这个行为不会耗费任何 CPU 资源，因为 JavaScript 引擎可以同时处理其他任务：执行其他脚本，处理事件等。

相比于 `promise.then`，它只是获取 promise 的结果的一个更优雅的语法。并且也更易于读写。

*注意：不能在普通的函数中使用 await*

现在将之前的例子修改下：

```js
async function showAvatar() {

  // 读取我们的 JSON
  let response = await fetch('/article/promise-chaining/user.json');
  let user = await response.json();

  // 读取 github 用户信息
  let githubResponse = await fetch(`https://api.github.com/users/${user.name}`);
  let githubUser = await githubResponse.json();

  // 显示头像
  let img = document.createElement('img');
  img.src = githubUser.avatar_url;
  img.className = "promise-avatar-example";
  document.body.append(img);

  // 等待 3 秒
  await new Promise((resolve, reject) => setTimeout(resolve, 3000));

  img.remove();

  return githubUser;
}

showAvatar();
```

这样更容易理解。

`await` 接受 `thenables`

像 `promise.then` 那样，`await` 允许我们使用 thenable 对象（那些具有可调用的 `then` 方法的对象）。这里的想法是，第三方对象可能不是一个 promise，但却是 promise 兼容的：如果这些对象支持 `.then`，那么就可以对它们使用 `await`。

这有一个用于演示的 `Thenable` 类，下面的 `await` 接受了该类的实例：

```js
class Thenable {
  constructor(num) {
    this.num = num;
  }
  then(resolve, reject) {
    alert(resolve);
    // 1000ms 后使用 this.num*2 进行 resolve
    setTimeout(() => resolve(this.num * 2), 1000); // (*)
  }
}

async function f() {
  // 等待 1 秒，之后 result 变为 2
  let result = await new Thenable(1);
  alert(result);
}

f();
```

如果 `await` 接收了一个非 promise 的但是提供了 `.then` 方法的对象，它就会调用这个 `.then` 方法，并将内建的函数 `resolve` 和 `reject` 作为参数传入（就像它对待一个常规的 `Promise` executor 时一样）。然后 `await` 等待直到这两个函数中的某个被调用（在上面这个例子中发生在 `(*)` 行），然后使用得到的结果继续执行后续任务。

Class 中的 async 方法

```js
class Waiter {
  async wait() {
    return await Promise.resolve(1);
  }
}

new Waiter()
  .wait()
  .then(alert); // 1（alert 等同于 result => alert(result)）
```



### Error 处理

如果一个 promise 正常 resolve，`await promise` 返回的就是其结果。但是如果 promise 被 reject，它将 throw 这个 error，就像在这一行有一个 `throw` 语句那样。

这个代码：
```js
async function f() {
  await Promise.reject(new Error("Whoops!"));
}
```

和下面是一样的

```js
async function f() {
  throw new Error("Whoops!");
}
```

在真实开发中，promise 可能需要一点时间后才 reject。在这种情况下，在 `await` 抛出（throw）一个 error 之前会有一个延时。

我们可以用 `try..catch` 来捕获上面提到的那个 error，与常规的 `throw` 使用的是一样的方式：

```js
async function f() {
  try {
    let response = await fetch('http://no-such-url');
  } catch(err) {
    alert(err); // TypeError: failed to fetch
  }
}

f();
```

如果我们没有 `try..catch`，那么由异步函数 `f()` 的调用生成的 promise 将变为 rejected。我们可以在函数调用后面添加 `.catch` 来处理这个 error：

```js
async function f() {
  let response = await fetch('http://no-such-url');
}

// f() 变成了一个 rejected 的 promise
f().catch(alert); // TypeError: failed to fetch // (*)
```

`async/await` 和 `promise.then/catch`

当我们使用 `async/await` 时，几乎就不会用到 `.then` 了，因为 `await` 为我们处理了等待。并且我们使用常规的 `try..catch` 而不是 `.catch`。这通常（但不总是）更加方便。

但是当我们在代码的顶层时，也就是在所有 `async` 函数之外，我们在语法上就不能使用 `await` 了，所以这时候通常的做法是添加 `.then/catch` 来处理最终的结果（result）或掉出来的（falling-through）error，例如像上面那个例子中的 `(*)` 行那样。


`async/await` 可以和 `Promise.all` 一起使用

当我们需要同时等待多个 promise 时，我们可以用 `Promise.all` 把它们包装起来，然后使用 `await`：

```js
// 等待结果数组
let results = await Promise.all([
  fetch(url1),
  fetch(url2),
  ...
]);
```

如果出现 error，也会正常传递，从失败了的 promise 传到 `Promise.all`，然后变成我们能通过使用 `try..catch` 在调用周围捕获到的异常（exception）。







