
```toc
```


## 错误处理

### `try..catch` 语法

```js
try {

  // 代码...

} catch (err) {

  // 错误捕获

}
```

仅对运行时的 error 有效。要使得 `try...catch` 能工作，代码必须是可执行的。换句话说，它必须是有效的 JavaScript 代码。

如果代码包含语法错误，那么 `try..catch` 将无法正常工作，例如含有不匹配的花括号：

```js
try {
  {{{{{{{{{{{{
} catch (err) {
  alert("引擎无法理解这段代码，它是无效的");
}
```


如果在“计划的（scheduled）”代码中发生异常，例如在 `setTimeout` 中，则 `try...catch` 不会捕获到异常：

```js
try {
  setTimeout(function() {
    noSuchVariable; // 脚本将在这里停止运行
  }, 1000);
} catch (err) {
  alert( "不工作" );
}
```

因为 `try...catch` 包裹了计划要执行的函数，该函数本身要稍后才执行，这时引擎已经离开了 `try...catch` 结构。

可以进行修改

```js
setTimeout(function() {
  try {
    noSuchVariable; // try...catch 处理 error 了！
  } catch {
    alert( "error 被在这里捕获了！" );
  }
}, 1000);
```


### Error 对象

对于所有内建的 error，error 对象具有两个主要属性：

`name` - Error 名称。例如，对于一个未定义的变量，名称是 `"ReferenceError"`。
`message` - 关于 error 的详细文字描述。

还有其他非标准的属性在大多数环境中可用。其中被最广泛使用和支持的是：

`stack` - 当前的调用栈：用于调试目的的一个字符串，其中包含有关导致 error 的嵌套调用序列的信息。

```js
try {
  lalala; // error, variable is not defined!
} catch (err) {
  alert(err.name); // ReferenceError
  alert(err.message); // lalala is not defined
  alert(err.stack); // ReferenceError: lalala is not defined at (...call stack)

  // 也可以将一个 error 作为整体显示出来
  // error 信息被转换为像 "name: message" 这样的字符串
  alert(err); // ReferenceError: lalala is not defined
}
```

### 可选的 catch 绑定

如果不需要 error 信息，catch 可以忽略

```js
try {
  // ...
} catch { // <-- 没有 (err)
  // ...
}
```

### throw 操作符

```js
let error = new Error(message);
// 或
let error = new SyntaxError(message);
let error = new ReferenceError(message);
// ...
```

### `try..catch..finally`

```js
try {
   ... 尝试执行的代码 ...
} catch (err) {
   ... 处理 error ...
} finally {
   ... 总是会执行的代码 ...
}
```



## 自定义 Error，扩展 Error

`Error` 类是内建的，但这是其近似代码，所以我们可以了解我们要扩展的内容：

```js
// JavaScript 自身定义的内建的 Error 类的“伪代码”
class Error {
  constructor(message) {
    this.message = message;
    this.name = "Error"; // (不同的内建 error 类有不同的名字)
    this.stack = <call stack>; // 非标准的，但大多数环境都支持它
  }
}
```

现在让我们从其中继承 `ValidationError`，并尝试进行运行：

```js
class ValidationError extends Error {
  constructor(message) {
    super(message); // (1)
    this.name = "ValidationError"; // (2)
  }
}

function test() {
  throw new ValidationError("Whoops!");
}

try {
  test();
} catch(err) {
  alert(err.message); // Whoops!
  alert(err.name); // ValidationError
  alert(err.stack); // 一个嵌套调用的列表，每个调用都有对应的行号
}
```